2023-05-08 11:36:25,614 ERROR: Exception on /view [GET] [in /home/timo/miniconda3/envs/archpy_env/lib/python3.10/site-packages/flask/app.py:1744]
Traceback (most recent call last):
  File "/home/timo/miniconda3/envs/archpy_env/lib/python3.10/site-packages/flask/app.py", line 2528, in wsgi_app
    response = self.full_dispatch_request()
  File "/home/timo/miniconda3/envs/archpy_env/lib/python3.10/site-packages/flask/app.py", line 1825, in full_dispatch_request
    rv = self.handle_user_exception(e)
  File "/home/timo/miniconda3/envs/archpy_env/lib/python3.10/site-packages/flask/app.py", line 1823, in full_dispatch_request
    rv = self.dispatch_request()
  File "/home/timo/miniconda3/envs/archpy_env/lib/python3.10/site-packages/flask/app.py", line 1799, in dispatch_request
    return self.ensure_sync(self.view_functions[rule.endpoint])(**view_args)
  File "/home/timo/miniconda3/envs/archpy_env/lib/python3.10/site-packages/flask_login/utils.py", line 290, in decorated_view
    return current_app.ensure_sync(func)(*args, **kwargs)
  File "/home/timo/Documents/Prototype/app/routes.py", line 173, in view
    realizations = zoom(realizations, (0.5, 0.5, 0.5))
  File "/home/timo/.local/lib/python3.10/site-packages/scipy/ndimage/_interpolation.py", line 770, in zoom
    zoom = _ni_support._normalize_sequence(zoom, input.ndim)
  File "/home/timo/.local/lib/python3.10/site-packages/scipy/ndimage/_ni_support.py", line 67, in _normalize_sequence
    raise RuntimeError(err)
RuntimeError: sequence argument must have length equal to input rank
2023-05-08 11:38:06,723 INFO: Application [in /home/timo/Documents/Prototype/app/__init__.py:42]
2023-05-08 11:38:37,764 INFO: Application [in /home/timo/Documents/Prototype/app/__init__.py:42]
2023-05-08 11:45:41,582 INFO: Application [in /home/timo/Documents/Prototype/app/__init__.py:42]
2023-05-08 11:46:49,567 INFO: Application [in /home/timo/Documents/Prototype/app/__init__.py:42]
2023-05-08 11:53:00,834 INFO: Application [in /home/timo/Documents/Prototype/app/__init__.py:42]
2023-05-08 11:54:38,774 INFO: Application [in /home/timo/Documents/Prototype/app/__init__.py:42]
2023-05-08 11:56:13,390 INFO: Application [in /home/timo/Documents/Prototype/app/__init__.py:42]
2023-05-08 11:58:03,670 INFO: Application [in /home/timo/Documents/Prototype/app/__init__.py:42]
2023-05-08 11:58:10,872 INFO: Application [in /home/timo/Documents/Prototype/app/__init__.py:42]
2023-05-08 11:59:14,874 INFO: Application [in /home/timo/Documents/Prototype/app/__init__.py:42]
2023-05-08 12:11:42,555 INFO: Application [in /home/timo/Documents/Prototype/app/__init__.py:42]
2023-05-08 12:11:47,928 ERROR: Exception on /view [GET] [in /home/timo/miniconda3/envs/archpy_env/lib/python3.10/site-packages/flask/app.py:1744]
Traceback (most recent call last):
  File "/home/timo/miniconda3/envs/archpy_env/lib/python3.10/site-packages/flask/app.py", line 2528, in wsgi_app
    response = self.full_dispatch_request()
  File "/home/timo/miniconda3/envs/archpy_env/lib/python3.10/site-packages/flask/app.py", line 1825, in full_dispatch_request
    rv = self.handle_user_exception(e)
  File "/home/timo/miniconda3/envs/archpy_env/lib/python3.10/site-packages/flask/app.py", line 1823, in full_dispatch_request
    rv = self.dispatch_request()
  File "/home/timo/miniconda3/envs/archpy_env/lib/python3.10/site-packages/flask/app.py", line 1799, in dispatch_request
    return self.ensure_sync(self.view_functions[rule.endpoint])(**view_args)
  File "/home/timo/miniconda3/envs/archpy_env/lib/python3.10/site-packages/flask_login/utils.py", line 290, in decorated_view
    return current_app.ensure_sync(func)(*args, **kwargs)
  File "/home/timo/Documents/Prototype/app/routes.py", line 191, in view
    return render_template('view2.html', plot=html, submission=submission)
  File "/home/timo/miniconda3/envs/archpy_env/lib/python3.10/site-packages/flask/templating.py", line 146, in render_template
    template = app.jinja_env.get_or_select_template(template_name_or_list)
  File "/home/timo/.local/lib/python3.10/site-packages/jinja2/environment.py", line 1081, in get_or_select_template
    return self.get_template(template_name_or_list, parent, globals)
  File "/home/timo/.local/lib/python3.10/site-packages/jinja2/environment.py", line 1010, in get_template
    return self._load_template(name, globals)
  File "/home/timo/.local/lib/python3.10/site-packages/jinja2/environment.py", line 969, in _load_template
    template = self.loader.load(self, name, self.make_globals(globals))
  File "/home/timo/.local/lib/python3.10/site-packages/jinja2/loaders.py", line 126, in load
    source, filename, uptodate = self.get_source(environment, name)
  File "/home/timo/miniconda3/envs/archpy_env/lib/python3.10/site-packages/flask/templating.py", line 62, in get_source
    return self._get_source_fast(environment, template)
  File "/home/timo/miniconda3/envs/archpy_env/lib/python3.10/site-packages/flask/templating.py", line 98, in _get_source_fast
    raise TemplateNotFound(template)
jinja2.exceptions.TemplateNotFound: view2.html
2023-05-08 12:11:57,327 INFO: Application [in /home/timo/Documents/Prototype/app/__init__.py:42]
2023-05-08 12:12:07,752 ERROR: Exception on /download [GET] [in /home/timo/miniconda3/envs/archpy_env/lib/python3.10/site-packages/flask/app.py:1744]
Traceback (most recent call last):
  File "/home/timo/miniconda3/envs/archpy_env/lib/python3.10/site-packages/flask/app.py", line 2528, in wsgi_app
    response = self.full_dispatch_request()
  File "/home/timo/miniconda3/envs/archpy_env/lib/python3.10/site-packages/flask/app.py", line 1825, in full_dispatch_request
    rv = self.handle_user_exception(e)
  File "/home/timo/miniconda3/envs/archpy_env/lib/python3.10/site-packages/flask/app.py", line 1823, in full_dispatch_request
    rv = self.dispatch_request()
  File "/home/timo/miniconda3/envs/archpy_env/lib/python3.10/site-packages/flask/app.py", line 1799, in dispatch_request
    return self.ensure_sync(self.view_functions[rule.endpoint])(**view_args)
  File "/home/timo/miniconda3/envs/archpy_env/lib/python3.10/site-packages/flask_login/utils.py", line 290, in decorated_view
    return current_app.ensure_sync(func)(*args, **kwargs)
  File "/home/timo/Documents/Prototype/app/routes.py", line 216, in download
    return send_file(path, as_attachment=True)
NameError: name 'send_file' is not defined
2023-05-08 12:12:29,994 INFO: Application [in /home/timo/Documents/Prototype/app/__init__.py:42]
2023-05-08 12:12:58,586 INFO: Application [in /home/timo/Documents/Prototype/app/__init__.py:42]
2023-05-08 12:16:56,897 INFO: Application [in /home/timo/Documents/Prototype/app/__init__.py:42]
2023-05-08 12:18:31,729 INFO: Application [in /home/timo/Documents/Prototype/app/__init__.py:42]
2023-05-08 12:18:59,667 INFO: Application [in /home/timo/Documents/Prototype/app/__init__.py:42]
2023-05-08 12:20:00,459 INFO: Application [in /home/timo/Documents/Prototype/app/__init__.py:42]
2023-05-08 12:20:44,839 INFO: Application [in /home/timo/Documents/Prototype/app/__init__.py:42]
