2023-04-24 16:53:32,741 ERROR: Exception on /model [POST] [in /home/timo/miniconda3/envs/archpy_env/lib/python3.10/site-packages/flask/app.py:1744]
Traceback (most recent call last):
  File "/home/timo/miniconda3/envs/archpy_env/lib/python3.10/site-packages/flask/app.py", line 2528, in wsgi_app
    response = self.full_dispatch_request()
  File "/home/timo/miniconda3/envs/archpy_env/lib/python3.10/site-packages/flask/app.py", line 1825, in full_dispatch_request
    rv = self.handle_user_exception(e)
  File "/home/timo/miniconda3/envs/archpy_env/lib/python3.10/site-packages/flask/app.py", line 1823, in full_dispatch_request
    rv = self.dispatch_request()
  File "/home/timo/miniconda3/envs/archpy_env/lib/python3.10/site-packages/flask/app.py", line 1799, in dispatch_request
    return self.ensure_sync(self.view_functions[rule.endpoint])(**view_args)
  File "/home/timo/miniconda3/envs/archpy_env/lib/python3.10/site-packages/flask_login/utils.py", line 290, in decorated_view
    return current_app.ensure_sync(func)(*args, **kwargs)
  File "/home/timo/Documents/Prototype/app/routes.py", line 118, in model
    rq_job = app.task_queue.enqueue(job)
  File "/home/timo/miniconda3/envs/archpy_env/lib/python3.10/site-packages/rq/queue.py", line 877, in enqueue
    return self.enqueue_call(
  File "/home/timo/miniconda3/envs/archpy_env/lib/python3.10/site-packages/rq/queue.py", line 649, in enqueue_call
    job = self.create_job(
  File "/home/timo/miniconda3/envs/archpy_env/lib/python3.10/site-packages/rq/queue.py", line 519, in create_job
    job = self.job_class.create(
  File "/home/timo/miniconda3/envs/archpy_env/lib/python3.10/site-packages/rq/job.py", line 232, in create
    raise TypeError('Expected a callable or a string, but got: {0}'.format(func))
TypeError: Expected a callable or a string, but got: <Job a8e2c0b4-6a2e-4699-aebf-a6d64e0dce05: tasks.run_geo_model('Demo', (50, 50, 50), (1.0, 1.0, 0.1))>
2023-04-24 16:54:07,994 INFO: Application [in /home/timo/Documents/Prototype/app/__init__.py:37]
2023-04-24 16:54:13,272 ERROR: Exception on /model [POST] [in /home/timo/miniconda3/envs/archpy_env/lib/python3.10/site-packages/flask/app.py:1744]
Traceback (most recent call last):
  File "/home/timo/miniconda3/envs/archpy_env/lib/python3.10/site-packages/flask/app.py", line 2528, in wsgi_app
    response = self.full_dispatch_request()
  File "/home/timo/miniconda3/envs/archpy_env/lib/python3.10/site-packages/flask/app.py", line 1825, in full_dispatch_request
    rv = self.handle_user_exception(e)
  File "/home/timo/miniconda3/envs/archpy_env/lib/python3.10/site-packages/flask/app.py", line 1823, in full_dispatch_request
    rv = self.dispatch_request()
  File "/home/timo/miniconda3/envs/archpy_env/lib/python3.10/site-packages/flask/app.py", line 1799, in dispatch_request
    return self.ensure_sync(self.view_functions[rule.endpoint])(**view_args)
  File "/home/timo/miniconda3/envs/archpy_env/lib/python3.10/site-packages/flask_login/utils.py", line 290, in decorated_view
    return current_app.ensure_sync(func)(*args, **kwargs)
  File "/home/timo/Documents/Prototype/app/routes.py", line 118, in model
    rq_job = app.task_queue.enqueue(job)
  File "/home/timo/miniconda3/envs/archpy_env/lib/python3.10/site-packages/rq/queue.py", line 877, in enqueue
    return self.enqueue_call(
  File "/home/timo/miniconda3/envs/archpy_env/lib/python3.10/site-packages/rq/queue.py", line 649, in enqueue_call
    job = self.create_job(
  File "/home/timo/miniconda3/envs/archpy_env/lib/python3.10/site-packages/rq/queue.py", line 519, in create_job
    job = self.job_class.create(
  File "/home/timo/miniconda3/envs/archpy_env/lib/python3.10/site-packages/rq/job.py", line 232, in create
    raise TypeError('Expected a callable or a string, but got: {0}'.format(func))
TypeError: Expected a callable or a string, but got: <Job fee4e2c5-8d39-4c5d-a63c-c7390f94feb6: tasks.run_geo_model('Demo', (50, 50, 50), (1.0, 1.0, 0.1))>
2023-04-24 16:54:48,910 INFO: Application [in /home/timo/Documents/Prototype/app/__init__.py:37]
