2023-04-24 16:42:04,003 ERROR: Exception on /model [POST] [in /home/timo/miniconda3/envs/archpy_env/lib/python3.10/site-packages/flask/app.py:1744]
Traceback (most recent call last):
  File "/home/timo/miniconda3/envs/archpy_env/lib/python3.10/site-packages/flask/app.py", line 2528, in wsgi_app
    response = self.full_dispatch_request()
  File "/home/timo/miniconda3/envs/archpy_env/lib/python3.10/site-packages/flask/app.py", line 1825, in full_dispatch_request
    rv = self.handle_user_exception(e)
  File "/home/timo/miniconda3/envs/archpy_env/lib/python3.10/site-packages/flask/app.py", line 1823, in full_dispatch_request
    rv = self.dispatch_request()
  File "/home/timo/miniconda3/envs/archpy_env/lib/python3.10/site-packages/flask/app.py", line 1799, in dispatch_request
    return self.ensure_sync(self.view_functions[rule.endpoint])(**view_args)
  File "/home/timo/miniconda3/envs/archpy_env/lib/python3.10/site-packages/flask_login/utils.py", line 290, in decorated_view
    return current_app.ensure_sync(func)(*args, **kwargs)
  File "/home/timo/Documents/Prototype/app/routes.py", line 115, in model
    job = Job.create('tasks.run_geo_model', args=(name, dim, spacing))
  File "/home/timo/miniconda3/envs/archpy_env/lib/python3.10/site-packages/rq/job.py", line 212, in create
    job = cls(connection=connection, serializer=serializer)
  File "/home/timo/miniconda3/envs/archpy_env/lib/python3.10/site-packages/rq/job.py", line 558, in __init__
    self.connection = resolve_connection(connection)
  File "/home/timo/miniconda3/envs/archpy_env/lib/python3.10/site-packages/rq/connections.py", line 115, in resolve_connection
    raise NoRedisConnectionException('Could not resolve a Redis connection')
rq.connections.NoRedisConnectionException: Could not resolve a Redis connection
2023-04-24 16:42:08,722 ERROR: Exception on /model [POST] [in /home/timo/miniconda3/envs/archpy_env/lib/python3.10/site-packages/flask/app.py:1744]
Traceback (most recent call last):
  File "/home/timo/miniconda3/envs/archpy_env/lib/python3.10/site-packages/flask/app.py", line 2528, in wsgi_app
    response = self.full_dispatch_request()
  File "/home/timo/miniconda3/envs/archpy_env/lib/python3.10/site-packages/flask/app.py", line 1825, in full_dispatch_request
    rv = self.handle_user_exception(e)
  File "/home/timo/miniconda3/envs/archpy_env/lib/python3.10/site-packages/flask/app.py", line 1823, in full_dispatch_request
    rv = self.dispatch_request()
  File "/home/timo/miniconda3/envs/archpy_env/lib/python3.10/site-packages/flask/app.py", line 1799, in dispatch_request
    return self.ensure_sync(self.view_functions[rule.endpoint])(**view_args)
  File "/home/timo/miniconda3/envs/archpy_env/lib/python3.10/site-packages/flask_login/utils.py", line 290, in decorated_view
    return current_app.ensure_sync(func)(*args, **kwargs)
  File "/home/timo/Documents/Prototype/app/routes.py", line 115, in model
    job = Job.create('tasks.run_geo_model', args=(name, dim, spacing))
  File "/home/timo/miniconda3/envs/archpy_env/lib/python3.10/site-packages/rq/job.py", line 212, in create
    job = cls(connection=connection, serializer=serializer)
  File "/home/timo/miniconda3/envs/archpy_env/lib/python3.10/site-packages/rq/job.py", line 558, in __init__
    self.connection = resolve_connection(connection)
  File "/home/timo/miniconda3/envs/archpy_env/lib/python3.10/site-packages/rq/connections.py", line 115, in resolve_connection
    raise NoRedisConnectionException('Could not resolve a Redis connection')
rq.connections.NoRedisConnectionException: Could not resolve a Redis connection
2023-04-24 16:45:02,998 INFO: Application [in /home/timo/Documents/Prototype/app/__init__.py:37]
2023-04-24 16:45:06,450 ERROR: Exception on /model [POST] [in /home/timo/miniconda3/envs/archpy_env/lib/python3.10/site-packages/flask/app.py:1744]
Traceback (most recent call last):
  File "/home/timo/miniconda3/envs/archpy_env/lib/python3.10/site-packages/flask/app.py", line 2528, in wsgi_app
    response = self.full_dispatch_request()
  File "/home/timo/miniconda3/envs/archpy_env/lib/python3.10/site-packages/flask/app.py", line 1825, in full_dispatch_request
    rv = self.handle_user_exception(e)
  File "/home/timo/miniconda3/envs/archpy_env/lib/python3.10/site-packages/flask/app.py", line 1823, in full_dispatch_request
    rv = self.dispatch_request()
  File "/home/timo/miniconda3/envs/archpy_env/lib/python3.10/site-packages/flask/app.py", line 1799, in dispatch_request
    return self.ensure_sync(self.view_functions[rule.endpoint])(**view_args)
  File "/home/timo/miniconda3/envs/archpy_env/lib/python3.10/site-packages/flask_login/utils.py", line 290, in decorated_view
    return current_app.ensure_sync(func)(*args, **kwargs)
  File "/home/timo/Documents/Prototype/app/routes.py", line 115, in model
    job = Job('tasks.run_geo_model', name, dim, spacing)
TypeError: Job.__init__() takes from 1 to 4 positional arguments but 5 were given
2023-04-24 16:45:26,120 INFO: Application [in /home/timo/Documents/Prototype/app/__init__.py:37]
2023-04-24 16:45:29,116 ERROR: Exception on /model [POST] [in /home/timo/miniconda3/envs/archpy_env/lib/python3.10/site-packages/flask/app.py:1744]
Traceback (most recent call last):
  File "/home/timo/miniconda3/envs/archpy_env/lib/python3.10/site-packages/flask/app.py", line 2528, in wsgi_app
    response = self.full_dispatch_request()
  File "/home/timo/miniconda3/envs/archpy_env/lib/python3.10/site-packages/flask/app.py", line 1825, in full_dispatch_request
    rv = self.handle_user_exception(e)
  File "/home/timo/miniconda3/envs/archpy_env/lib/python3.10/site-packages/flask/app.py", line 1823, in full_dispatch_request
    rv = self.dispatch_request()
  File "/home/timo/miniconda3/envs/archpy_env/lib/python3.10/site-packages/flask/app.py", line 1799, in dispatch_request
    return self.ensure_sync(self.view_functions[rule.endpoint])(**view_args)
  File "/home/timo/miniconda3/envs/archpy_env/lib/python3.10/site-packages/flask_login/utils.py", line 290, in decorated_view
    return current_app.ensure_sync(func)(*args, **kwargs)
  File "/home/timo/Documents/Prototype/app/routes.py", line 115, in model
    job = Job('tasks.run_geo_model', args=(name, dim, spacing))
TypeError: Job.__init__() got an unexpected keyword argument 'args'
2023-04-24 16:47:01,613 INFO: Application [in /home/timo/Documents/Prototype/app/__init__.py:37]
2023-04-24 16:47:04,481 ERROR: Exception on /model [POST] [in /home/timo/miniconda3/envs/archpy_env/lib/python3.10/site-packages/flask/app.py:1744]
Traceback (most recent call last):
  File "/home/timo/miniconda3/envs/archpy_env/lib/python3.10/site-packages/flask/app.py", line 2528, in wsgi_app
    response = self.full_dispatch_request()
  File "/home/timo/miniconda3/envs/archpy_env/lib/python3.10/site-packages/flask/app.py", line 1825, in full_dispatch_request
    rv = self.handle_user_exception(e)
  File "/home/timo/miniconda3/envs/archpy_env/lib/python3.10/site-packages/flask/app.py", line 1823, in full_dispatch_request
    rv = self.dispatch_request()
  File "/home/timo/miniconda3/envs/archpy_env/lib/python3.10/site-packages/flask/app.py", line 1799, in dispatch_request
    return self.ensure_sync(self.view_functions[rule.endpoint])(**view_args)
  File "/home/timo/miniconda3/envs/archpy_env/lib/python3.10/site-packages/flask_login/utils.py", line 290, in decorated_view
    return current_app.ensure_sync(func)(*args, **kwargs)
  File "/home/timo/Documents/Prototype/app/routes.py", line 115, in model
    job = Job.create('tasks.run_geo_model', args=(name, dim, spacing))
  File "/home/timo/miniconda3/envs/archpy_env/lib/python3.10/site-packages/rq/job.py", line 212, in create
    job = cls(connection=connection, serializer=serializer)
  File "/home/timo/miniconda3/envs/archpy_env/lib/python3.10/site-packages/rq/job.py", line 558, in __init__
    self.connection = resolve_connection(connection)
  File "/home/timo/miniconda3/envs/archpy_env/lib/python3.10/site-packages/rq/connections.py", line 115, in resolve_connection
    raise NoRedisConnectionException('Could not resolve a Redis connection')
rq.connections.NoRedisConnectionException: Could not resolve a Redis connection
2023-04-24 16:47:35,730 INFO: Application [in /home/timo/Documents/Prototype/app/__init__.py:37]
2023-04-24 16:47:40,885 ERROR: Exception on /model [POST] [in /home/timo/miniconda3/envs/archpy_env/lib/python3.10/site-packages/flask/app.py:1744]
Traceback (most recent call last):
  File "/home/timo/miniconda3/envs/archpy_env/lib/python3.10/site-packages/flask/app.py", line 2528, in wsgi_app
    response = self.full_dispatch_request()
  File "/home/timo/miniconda3/envs/archpy_env/lib/python3.10/site-packages/flask/app.py", line 1825, in full_dispatch_request
    rv = self.handle_user_exception(e)
  File "/home/timo/miniconda3/envs/archpy_env/lib/python3.10/site-packages/flask/app.py", line 1823, in full_dispatch_request
    rv = self.dispatch_request()
  File "/home/timo/miniconda3/envs/archpy_env/lib/python3.10/site-packages/flask/app.py", line 1799, in dispatch_request
    return self.ensure_sync(self.view_functions[rule.endpoint])(**view_args)
  File "/home/timo/miniconda3/envs/archpy_env/lib/python3.10/site-packages/flask_login/utils.py", line 290, in decorated_view
    return current_app.ensure_sync(func)(*args, **kwargs)
  File "/home/timo/Documents/Prototype/app/routes.py", line 115, in model
    job = Job.create('tasks.run_geo_model', args=(name, dim, spacing))
  File "/home/timo/miniconda3/envs/archpy_env/lib/python3.10/site-packages/rq/job.py", line 212, in create
    job = cls(connection=connection, serializer=serializer)
  File "/home/timo/miniconda3/envs/archpy_env/lib/python3.10/site-packages/rq/job.py", line 558, in __init__
    self.connection = resolve_connection(connection)
  File "/home/timo/miniconda3/envs/archpy_env/lib/python3.10/site-packages/rq/connections.py", line 115, in resolve_connection
    raise NoRedisConnectionException('Could not resolve a Redis connection')
rq.connections.NoRedisConnectionException: Could not resolve a Redis connection
2023-04-24 16:53:26,969 INFO: Application [in /home/timo/Documents/Prototype/app/__init__.py:37]
