2023-04-22 17:34:36,845 ERROR: Exception on /index [GET] [in /home/timo/miniconda3/envs/archpy_env/lib/python3.10/site-packages/flask/app.py:1744]
Traceback (most recent call last):
  File "/home/timo/miniconda3/envs/archpy_env/lib/python3.10/site-packages/flask/app.py", line 2528, in wsgi_app
    response = self.full_dispatch_request()
  File "/home/timo/miniconda3/envs/archpy_env/lib/python3.10/site-packages/flask/app.py", line 1825, in full_dispatch_request
    rv = self.handle_user_exception(e)
  File "/home/timo/miniconda3/envs/archpy_env/lib/python3.10/site-packages/flask/app.py", line 1823, in full_dispatch_request
    rv = self.dispatch_request()
  File "/home/timo/miniconda3/envs/archpy_env/lib/python3.10/site-packages/flask/app.py", line 1799, in dispatch_request
    return self.ensure_sync(self.view_functions[rule.endpoint])(**view_args)
  File "/home/timo/Documents/Prototype/app/routes.py", line 20, in index
    return render_template('index.html', title='Home', submissions=submissions)
  File "/home/timo/miniconda3/envs/archpy_env/lib/python3.10/site-packages/flask/templating.py", line 147, in render_template
    return _render(app, template, context)
  File "/home/timo/miniconda3/envs/archpy_env/lib/python3.10/site-packages/flask/templating.py", line 130, in _render
    rv = template.render(context)
  File "/home/timo/.local/lib/python3.10/site-packages/jinja2/environment.py", line 1301, in render
    self.environment.handle_exception()
  File "/home/timo/.local/lib/python3.10/site-packages/jinja2/environment.py", line 936, in handle_exception
    raise rewrite_traceback_stack(source=source)
  File "/home/timo/Documents/Prototype/app/templates/index.html", line 1, in top-level template code
    {% extends "base.html" %}
  File "/home/timo/Documents/Prototype/app/templates/base.html", line 37, in top-level template code
    {% block content %}
  File "/home/timo/Documents/Prototype/app/templates/index.html", line 22, in block 'content'
    You can submit jobs <a href="{{ url_for('submission') }}">here</a>.
  File "/home/timo/miniconda3/envs/archpy_env/lib/python3.10/site-packages/flask/app.py", line 2034, in url_for
    return self.handle_url_build_error(error, endpoint, values)
  File "/home/timo/miniconda3/envs/archpy_env/lib/python3.10/site-packages/flask/app.py", line 2023, in url_for
    rv = url_adapter.build(  # type: ignore[union-attr]
  File "/home/timo/miniconda3/envs/archpy_env/lib/python3.10/site-packages/werkzeug/routing/map.py", line 917, in build
    raise BuildError(endpoint, values, method, self)
werkzeug.routing.exceptions.BuildError: Could not build url for endpoint 'submission'. Did you mean 'index' instead?
2023-04-22 17:35:03,472 INFO: Application [in /home/timo/Documents/Prototype/app/__init__.py:32]
2023-04-22 17:36:13,850 INFO: Application [in /home/timo/Documents/Prototype/app/__init__.py:32]
2023-04-22 17:38:14,254 INFO: Application [in /home/timo/Documents/Prototype/app/__init__.py:32]
2023-04-22 17:38:59,628 INFO: Application [in /home/timo/Documents/Prototype/app/__init__.py:32]
